Workbook

Sheet Summary
C3: Cedarwood Flats | Underwriting Model Summary
C5: SKU-level model built from user-authorized historical planning figures and editable projected assumptions. This workbook is an underwriting tool—not a record of actual performance.
C6: ($ in whole dollars unless noted)
C8: HISTORICAL PLANNING CONTROLS
C9: Metric | D9: Value | E9: Source / Formula | F9: Status | G9: Model Treatment
C10: Development cost control | D10: ='Inputs - SKU Register'!G10 -> 40000000 | E10: Authorized historical planning input | F10: Estimated historical planning | G10: Controls WBS reconciliation
C11: 100-line WBS total | D11: ='WBS Budget'!K110 -> 40000000 | E11: Linked WBS total | F11: Formula | G11: Budget control
C12: WBS reconciliation | D12: ='WBS Budget'!K111 -> 0 | E12: WBS total less $40M control | F12: Formula | G12: Must equal $0.0
C13: Program units | D13: ='Inputs - SKU Register'!G11 -> 280 | E13: Authorized historical planning input | F13: Estimated historical planning | G13: Program reference
C14: Buildings | D14: ='Inputs - SKU Register'!G12 -> 5 | E14: Authorized historical planning input | F14: Estimated historical planning | G14: Program reference
C15: Annual NOI reference | D15: ='Inputs - SKU Register'!G18 -> 4750000 | E15: Authorized historical planning input | F15: Estimated historical planning | G15: Reference only; not used to back-solve rents
C16: Historical yield on cost | D16: ='Inputs - SKU Register'!G19 -> 0.11875 | E16: $4.75M / $40M | F16: Derived historical planning | G16: Reference metric
C17: Financing reference | D17: ='Inputs - SKU Register'!G20 -> 55000000 | E17: Authorized historical planning input | F17: Estimated historical planning | G17: Reference only; not funded capital
C19: ACTIVE UNDERWRITING CASE STATUS
C20: Required Driver Block | D20: SKU Lines | E20: Completion | F20: What the Model Does
C21: Unit mix / market rent | D21: REV-* | E21: =COUNT('Rent Roll'!E10:E13)&" / 4 unit counts; "&COUNT('Rent Roll'!I10:I13)&" / 4 rents" -> 0 / 4 unit counts; 0 / 4 rents | F21: Activates gross potential rent when populated.
C22: Operating expenses | D22: OPX-* | E22: =COUNT('Revenue & Operations'!E17:E30)&" / 14 items" -> 0 / 14 items | F22: Activates EGI and NOI when populated.
C23: 36-month timing | D23: SCH-* | E23: =COUNT('Monthly Schedule'!F10:F45)&" / 36 construction; "&COUNT('Monthly Schedule'!I10:I45)&" / 36 occupancy" -> 0 / 36 construction; 0 / 36 occupancy | F23: Activates monthly construction and lease-up cash flow.
C24: Financing terms | D24: FIN-010 to FIN-017 | E24: =COUNT('Debt Schedule'!E10:E17)&" / 8 terms" -> 1 / 8 terms | F24: Activates debt service and levered cash flow.
C25: Exit / return drivers | D25: EXIT-* | E25: =COUNT('Inputs - SKU Register'!H148:H150)&" / 3 exit drivers" -> 0 / 3 exit drivers | F25: Supports exit and terminal-value analysis once entered.
C27: MODEL NAVIGATION
C28: Tab | D28: Purpose | E28: Required Action
C29: Inputs - SKU Register | D29: All required numbers have a SKU and source field. | E29: Enter blue-font Base / Downside / Upside input cells with source comments.
C30: WBS Budget | D30: 100 development budget entries totaling $40M. | E30: Use as the project cost control and replace allowances only with sourced revisions.
C31: Rent Roll | D31: Unit-type program and market-rent build. | E31: Enter unit counts, SF, rents, and occupancy by unit type.
C32: Revenue & Operations | D32: Stabilized operating statement. | E32: Enter each operating expense line; do not force the historical NOI reference.
C33: Monthly Schedule | D33: 36-month construction and lease-up timing. | E33: Enter construction deployment and occupancy each month.
C34: Sources & Uses / Debt Schedule | D34: Capital structure and debt mechanics. | E34: Enter active debt terms and actual intended sources.
C35: Returns | D35: Monthly levered cash flow and return calculations. | E35: Review only after the linked underlying schedules are complete.

Sheet Inputs - SKU Register
C3: Cedarwood Flats | SKU-Level Assumptions & Input Register
C5: Every number required by the underwriting model is represented below. Blue-font cells are hardcoded planning inputs; blank blue-font cells require entry.
C6: ($ in whole dollars unless noted)
C8: AUTHORIZED HISTORICAL PLANNING INPUTS AND EDITABLE UNDERWRITING DRIVERS
C9: SKU | D9: Input Category | E9: Driver / Number Required | F9: Unit | G9: Historical Planning | H9: Base Case | I9: Downside | J9: Upside | K9: Input State | L9: Source / Provenance | M9: Effective Date | N9: Owner | O9: Feeds Schedule | P9: Notes
C10: PRJ-001 | D10: Project control | E10: Total development cost control | F10: USD | G10: 40000000 | H10: 40000000 | K10: Estimated historical planning base case | L10: User-authorized historical planning briefing (pasted_content_21.txt, received 2026-08-21); effective date unknown; estimated historical planning context, not actuals or commitments. | N10: jchappell2120 | O10: Summary / WBS / Sources & Uses | P10: Authorized $40M reverse-engineering control case, carried to the working base-case control.
C11: PRJ-002 | D11: Project program | E11: Total unit count | F11: units | G11: 280 | H11: 280 | K11: Estimated historical planning base case | L11: User-authorized historical planning briefing (pasted_content_21.txt, received 2026-08-21); effective date unknown; estimated historical planning context, not actuals or commitments. | N11: jchappell2120 | O11: Rent Roll / Summary | P11: Working program control; unit mix by bedroom type remains an editable planning input.
C12: PRJ-003 | D12: Project program | E12: Building count | F12: buildings | G12: 5 | H12: 5 | K12: Estimated historical planning base case | L12: User-authorized historical planning briefing (pasted_content_21.txt, received 2026-08-21); effective date unknown; estimated historical planning context, not actuals or commitments. | N12: jchappell2120 | O12: Summary | P12: Five-building program reference carried to the working base case.
C13: PRJ-004 | D13: Project program | E13: Average SF per unit | F13: SF / unit | G13: 893 | H13: 893 | K13: Derived historical planning quantity | L13: User-authorized historical planning briefing (pasted_content_21.txt, received 2026-08-21); effective date unknown; estimated historical planning context, not actuals or commitments. | N13: jchappell2120 | O13: Rent Roll | P13: Derived from 250,000 gross SF / 280 units; planning reference carried to base.
C14: PRJ-005 | D14: Cost basis | E14: Low construction cost basis | F14: USD / SF | G14: 155 | H14: 155 | K14: Estimated historical planning base case | L14: User-authorized historical planning briefing (pasted_content_21.txt, received 2026-08-21); effective date unknown; estimated historical planning context, not actuals or commitments. | N14: jchappell2120 | O14: Cost Basis Sensitivity | P14: Supplied historical sensitivity.
C15: PRJ-006 | D15: Cost basis | E15: Central construction cost basis | F15: USD / SF | G15: 160 | H15: 160 | K15: Estimated historical planning base case | L15: User-authorized historical planning briefing (pasted_content_21.txt, received 2026-08-21); effective date unknown; estimated historical planning context, not actuals or commitments. | N15: jchappell2120 | O15: Cost Basis Sensitivity | P15: Supplied historical sensitivity.
C16: PRJ-007 | D16: Cost basis | E16: High construction cost basis | F16: USD / SF | G16: 165 | H16: 165 | K16: Estimated historical planning base case | L16: User-authorized historical planning briefing (pasted_content_21.txt, received 2026-08-21); effective date unknown; estimated historical planning context, not actuals or commitments. | N16: jchappell2120 | O16: Cost Basis Sensitivity | P16: Supplied historical sensitivity.
C17: PRJ-008 | D17: Project program | E17: Central implied gross SF | F17: SF | G17: 250000 | H17: 250000 | K17: Derived historical planning quantity | L17: User-authorized historical planning briefing (pasted_content_21.txt, received 2026-08-21); effective date unknown; estimated historical planning context, not actuals or commitments. | N17: jchappell2120 | O17: Summary | P17: $40M / $160 per SF; not a confirmed measurement.
C18: PRJ-009 | D18: Operations reference | E18: Annual NOI reference | F18: USD / year | G18: 4750000 | H18: 4750000 | K18: Estimated historical planning base case | L18: User-authorized historical planning briefing (pasted_content_21.txt, received 2026-08-21); effective date unknown; estimated historical planning context, not actuals or commitments. | N18: jchappell2120 | O18: Summary / Returns | P18: Reference comparison only; never used to back-solve rents.
C19: PRJ-010 | D19: Operations reference | E19: Historical yield on cost | F19: % | G19: 0.11875 | H19: 0.11875 | K19: Derived historical planning metric | L19: User-authorized historical planning briefing (pasted_content_21.txt, received 2026-08-21); effective date unknown; estimated historical planning context, not actuals or commitments. | N19: jchappell2120 | O19: Summary / Returns | P19: $4.75M / $40M; reference metric only.
C20: FIN-001 | D20: Financing reference | E20: Historical financing reference | F20: USD | G20: 55000000 | K20: Historical planning reference | L20: User-authorized historical planning briefing (pasted_content_21.txt, received 2026-08-21); effective date unknown; estimated historical planning context, not actuals or commitments. | N20: jchappell2120 | O20: Sources & Uses | P20: Reference only; not funded capital and not applied to the active base case unless copied to a debt input.
C22: UNIT MIX AND MARKET RENT SKU INPUTS
C23: SKU | D23: Input Category | E23: Driver / Number Required | F23: Unit | G23: Historical Planning | H23: Base Case | I23: Downside | J23: Upside | K23: Input State | L23: Source / Provenance | M23: Effective Date | N23: Owner | O23: Feeds Schedule | P23: Notes
C24: REV-STUDIO-01 | D24: Unit mix | E24: Studio unit count | F24: units | K24: Projected — enter | L24: Model input required | N24: jchappell2120 | O24: Rent Roll | P24: Enter the planned unit count; all unit-type counts must reconcile to PRJ-002.
C25: REV-STUDIO-02 | D25: Unit mix | E25: Studio average square feet | F25: SF / unit | K25: Projected — enter | L25: Model input required | N25: jchappell2120 | O25: Rent Roll | P25: Enter planned average unit size.
C26: REV-STUDIO-03 | D26: Market rent | E26: Studio monthly market rent | F26: USD / unit / month | K26: Projected — enter | L26: Model input required | N26: jchappell2120 | O26: Rent Roll / Revenue | P26: Enter a source-labeled market rent. Do not enter a placeholder as a verified rent.
C27: REV-STUDIO-04 | D27: Lease-up | E27: Studio stabilized occupancy | F27: % | K27: Projected — enter | L27: Model input required | N27: jchappell2120 | O27: Rent Roll / Monthly Schedule | P27: Enter stabilized economic occupancy for this unit type.
C28: REV-ONEBR-01 | D28: Unit mix | E28: One bedroom unit count | F28: units | K28: Projected — enter | L28: Model input required | N28: jchappell2120 | O28: Rent Roll | P28: Enter the planned unit count; all unit-type counts must reconcile to PRJ-002.
C29: REV-ONEBR-02 | D29: Unit mix | E29: One bedroom average square feet | F29: SF / unit | K29: Projected — enter | L29: Model input required | N29: jchappell2120 | O29: Rent Roll | P29: Enter planned average unit size.
C30: REV-ONEBR-03 | D30: Market rent | E30: One bedroom monthly market rent | F30: USD / unit / month | K30: Projected — enter | L30: Model input required | N30: jchappell2120 | O30: Rent Roll / Revenue | P30: Enter a source-labeled market rent. Do not enter a placeholder as a verified rent.
C31: REV-ONEBR-04 | D31: Lease-up | E31: One bedroom stabilized occupancy | F31: % | K31: Projected — enter | L31: Model input required | N31: jchappell2120 | O31: Rent Roll / Monthly Schedule | P31: Enter stabilized economic occupancy for this unit type.
C32: REV-TWOBR-01 | D32: Unit mix | E32: Two bedroom unit count | F32: units | K32: Projected — enter | L32: Model input required | N32: jchappell2120 | O32: Rent Roll | P32: Enter the planned unit count; all unit-type counts must reconcile to PRJ-002.
C33: REV-TWOBR-02 | D33: Unit mix | E33: Two bedroom average square feet | F33: SF / unit | K33: Projected — enter | L33: Model input required | N33: jchappell2120 | O33: Rent Roll | P33: Enter planned average unit size.
C34: REV-TWOBR-03 | D34: Market rent | E34: Two bedroom monthly market rent | F34: USD / unit / month | K34: Projected — enter | L34: Model input required | N34: jchappell2120 | O34: Rent Roll / Revenue | P34: Enter a source-labeled market rent. Do not enter a placeholder as a verified rent.
C35: REV-TWOBR-04 | D35: Lease-up | E35: Two bedroom stabilized occupancy | F35: % | K35: Projected — enter | L35: Model input required | N35: jchappell2120 | O35: Rent Roll / Monthly Schedule | P35: Enter stabilized economic occupancy for this unit type.
... C42: REV-023 | D42: Revenue timing | E42: Collections lag | F42: months | K42: Projected — enter | L42: Model input required | N42: jchappell2120 | O42: Monthly Schedule | P42: Enter collections timing assumption.
C44: OPERATING EXPENSE SKU INPUTS
C45: SKU | D45: Input Category | E45: Driver / Number Required | F45: Unit | G45: Historical Planning | H45: Base Case | I45: Downside | J45: Upside | K45: Input State | L45: Source / Provenance | M45: Effective Date | N45: Owner | O45: Feeds Schedule | P45: Notes
C46: OPX-001 | D46: Operating expense | E46: Real estate taxes | F46: USD / year | K46: Projected — enter | L46: Model input required | N46: jchappell2120 | O46: Revenue & Operations | P46: Enter annual stabilized amount with source and expense basis.
C47: OPX-002 | D47: Operating expense | E47: Property insurance | F47: USD / year | K47: Projected — enter | L47: Model input required | N47: jchappell2120 | O47: Revenue & Operations | P47: Enter annual stabilized amount with source and expense basis.
C48: OPX-003 | D48: Operating expense | E48: Property management | F48: USD / year | K48: Projected — enter | L48: Model input required | N48: jchappell2120 | O48: Revenue & Operations | P48: Enter annual stabilized amount with source and expense basis.
C49: OPX-004 | D49: Operating expense | E49: Payroll and benefits | F49: USD / year | K49: Projected — enter | L49: Model input required | N49: jchappell2120 | O49: Revenue & Operations | P49: Enter annual stabilized amount with source and expense basis.
C50: OPX-005 | D50: Operating expense | E50: Repairs and maintenance | F50: USD / year | K50: Projected — enter | L50: Model input required | N50: jchappell2120 | O50: Revenue & Operations | P50: Enter annual stabilized amount with source and expense basis.
C51: OPX-006 | D51: Operating expense | E51: Utilities | F51: USD / year | K51: Projected — enter | L51: Model input required | N51: jchappell2120 | O51: Revenue & Operations | P51: Enter annual stabilized amount with source and expense basis.
C52: OPX-007 | D52: Operating expense | E52: Contract services | F52: USD / year | K52: Projected — enter | L52: Model input required | N52: jchappell2120 | O52: Revenue & Operations | P52: Enter annual stabilized amount with source and expense basis.
...

Sheet WBS Budget
C3: Cedarwood Flats | 100-Line Development Budget
C5: 100 reverse-engineered historical planning allocations that reconcile to the authorized $40M control. These are planning entries, not invoices, bids, or commitments.
C6: ($ in whole dollars unless noted)
C8: DEVELOPMENT BUDGET — 100 SKU-LIKE WBS ENTRIES
C9: SKU | D9: Cost Category | E9: Phase | F9: Description | G9: Building Applicability | H9: Quantity | I9: Unit | J9: Unit Cost | K9: Budget Amount | L9: % of Total | M9: Data State | N9: Source Classification | O9: Source / Provenance | P9: Notes
C10: WBS-001 | D10: land_acquisition | E10: predevelopment | F10: Land acquisition consideration | G10: Project-wide | H10: 1 | I10: planning_allowance | J10: 3400000 | K10: 3400000 | L10: =K10/$K$110 -> 0.085 | M10: Estimated | N10: Reverse-engineered historical planning allocation | O10: User-authorized historical planning briefing (pasted_content_21.txt, received 2026-08-21) | P10: Historical planning allocation; not an actual invoice, bid, commitment, or funded-capital record.
C11: WBS-002 | D11: land_acquisition | E11: predevelopment | F11: Acquisition due diligence | G11: Project-wide | H11: 1 | I11: planning_allowance | J11: 150000 | K11: 150000 | L11: =K11/$K$110 -> 0.00375 | M11: Estimated | N11: Reverse-engineered historical planning allocation | O11: User-authorized historical planning briefing (pasted_content_21.txt, received 2026-08-21) | P11: Historical planning allocation; not an actual invoice, bid, commitment, or funded-capital record.
C12: WBS-003 | D12: land_acquisition | E12: predevelopment | F12: Title and escrow | G12: Project-wide | H12: 1 | I12: planning_allowance | J12: 50000 | K12: 50000 | L12: =K12/$K$110 -> 0.00125 | M12: Estimated | N12: Reverse-engineered historical planning allocation | O12: User-authorized historical planning briefing (pasted_content_21.txt, received 2026-08-21) | P12: Historical planning allocation; not an actual invoice, bid, commitment, or funded-capital record.
C13: WBS-004 | D13: land_acquisition | E13: predevelopment | F13: Acquisition legal | G13: Project-wide | H13: 1 | I13: planning_allowance | J13: 50000 | K13: 50000 | L13: =K13/$K$110 -> 0.00125 | M13: Estimated | N13: Reverse-engineered historical planning allocation | O13: User-authorized historical planning briefing (pasted_content_21.txt, received 2026-08-21) | P13: Historical planning allocation; not an actual invoice, bid, commitment, or funded-capital record.
C14: WBS-005 | D14: land_acquisition | E14: predevelopment | F14: Environmental review | G14: Project-wide | H14: 1 | I14: planning_allowance | J14: 50000 | K14: 50000 | L14: =K14/$K$110 -> 0.00125 | M14: Estimated | N14: Reverse-engineered historical planning allocation | O14: User-authorized historical planning briefing (pasted_content_21.txt, received 2026-08-21) | P14: Historical planning allocation; not an actual invoice, bid, commitment, or funded-capital record.
C15: WBS-006 | D15: land_acquisition | E15: predevelopment | F15: Boundary and topographic survey | G15: Project-wide | H15: 1 | I15: planning_allowance | J15: 50000 | K15: 50000 | L15: =K15/$K$110 -> 0.00125 | M15: Estimated | N15: Reverse-engineered historical planning allocation | O15: User-authorized historical planning briefing (pasted_content_21.txt, received 2026-08-21) | P15: Historical planning allocation; not an actual invoice, bid, commitment, or funded-capital record.
C16: WBS-007 | D16: land_acquisition | E16: predevelopment | F16: Geotechnical investigation | G16: Project-wide | H16: 1 | I16: planning_allowance | J16: 75000 | K16: 75000 | L16: =K16/$K$110 -> 0.001875 | M16: Estimated | N16: Reverse-engineered historical planning allocation | O16: User-authorized historical planning briefing (pasted_content_21.txt, received 2026-08-21) | P16: Historical planning allocation; not an actual invoice, bid, commitment, or funded-capital record.
C17: WBS-008 | D17: land_acquisition | E17: predevelopment | F17: Acquisition brokerage | G17: Project-wide | H17: 1 | I17: planning_allowance | J17: 50000 | K17: 50000 | L17: =K17/$K$110 -> 0.00125 | M17: Estimated | N17: Reverse-engineered historical planning allocation | O17: User-authorized historical planning briefing (pasted_content_21.txt, received 2026-08-21) | P17: Historical planning allocation; not an actual invoice, bid, commitment, or funded-capital record.
C18: WBS-009 | D18: land_acquisition | E18: predevelopment | F18: Demolition and clearing allowance | G18: Project-wide | H18: 1 | I18: planning_allowance | J18: 50000 | K18: 50000 | L18: =K18/$K$110 -> 0.00125 | M18: Estimated | N18: Reverse-engineered historical planning allocation | O18: User-authorized historical planning briefing (pasted_content_21.txt, received 2026-08-21) | P18: Historical planning allocation; not an actual invoice, bid, commitment, or funded-capital record.
C19: WBS-010 | D19: land_acquisition | E19: predevelopment | F19: Land closing reserve | G19: Project-wide | H19: 1 | I19: planning_allowance | J19: 75000 | K19: 75000 | L19: =K19/$K$110 -> 0.001875 | M19: Estimated | N19: Reverse-engineered historical planning allocation | O19: User-authorized historical planning briefing (pasted_content_21.txt, received 2026-08-21) | P19: Historical planning allocation; not an actual invoice, bid, commitment, or funded-capital record.
C20: WBS-011 | D20: site_development | E20: construction | F20: Mass grading | G20: Project-wide | H20: 1 | I20: planning_allowance | J20: 700000 | K20: 700000 | L20: =K20/$K$110 -> 0.0175 | M20: Estimated | N20: Reverse-engineered historical planning allocation | O20: User-authorized historical planning briefing (pasted_content_21.txt, received 2026-08-21) | P20: Historical planning allocation; not an actual invoice, bid, commitment, or funded-capital record.
C21: WBS-012 | D21: site_development | E21: construction | F21: Utility extension | G21: Project-wide | H21: 1 | I21: planning_allowance | J21: 500000 | K21: 500000 | L21: =K21/$K$110 -> 0.0125 | M21: Estimated | N21: Reverse-engineered historical planning allocation | O21: User-authorized historical planning briefing (pasted_content_21.txt, received 2026-08-21) | P21: Historical planning allocation; not an actual invoice, bid, commitment, or funded-capital record.
... C109: WBS-100 | D109: contingency | E109: building_completion | F109: Closeout contingency | G109: Project-wide | H109: 1 | I109: planning_allowance | J109: 100000 | K109: 100000 | L109: =K109/$K$110 -> 0.0025 | M109: Estimated | N109: Reverse-engineered historical planning allocation | O109: User-authorized historical planning briefing (pasted_content_21.txt, received 2026-08-21) | P109: Historical planning allocation; not an actual invoice, bid, commitment, or funded-capital record.
C110: CHECK-001 | F110: Total Development Budget | K110: =SUM(K10:K109) -> 40000000 | L110: 1
F111: Reconciliation to $40M control | K111: =K110-'Inputs - SKU Register'!$G$10 -> 0 | P111: Must equal $0.0 before the planning budget is used as the development-cost control.

Sheet Rent Roll
C3: Cedarwood Flats | Rent Roll & Revenue Drivers
C5: All market rent, unit mix, and occupancy inputs are editable scenario drivers. The workbook does not back-solve rents from the NOI reference.
C6: ($ in whole dollars unless noted)
C8: BASE-CASE UNIT MIX AND MARKET RENT DRIVERS
C9: Unit Type | D9: Count SKU | E9: Count | F9: Average SF SKU | G9: Average SF | H9: Rent SKU | I9: Monthly Rent | J9: Occupancy SKU | K9: Occupancy | L9: Monthly GPR | M9: Monthly EGI | N9: Notes
C10: Studio | D10: REV-STUDIO-01 | E10: =IF('Inputs - SKU Register'!H24="","",'Inputs - SKU Register'!H24) | F10: REV-STUDIO-02 | G10: =IF('Inputs - SKU Register'!H25="","",'Inputs - SKU Register'!H25) | H10: REV-STUDIO-03 | I10: =IF('Inputs - SKU Register'!H26="","",'Inputs - SKU Register'!H26) | J10: REV-STUDIO-04 | K10: =IF('Inputs - SKU Register'!H27="","",'Inputs - SKU Register'!H27) | L10: =IF(OR(E10="",I10=""),"",E10*I10) | M10: =IF(OR(L10="",K10=""),"",L10*K10) | N10: Enter sourced market rent, planned count, average SF, and stabilized occupancy.
C11: One bedroom | D11: REV-ONEBR-01 | E11: =IF('Inputs - SKU Register'!H28="","",'Inputs - SKU Register'!H28) | F11: REV-ONEBR-02 | G11: =IF('Inputs - SKU Register'!H29="","",'Inputs - SKU Register'!H29) | H11: REV-ONEBR-03 | I11: =IF('Inputs - SKU Register'!H30="","",'Inputs - SKU Register'!H30) | J11: REV-ONEBR-04 | K11: =IF('Inputs - SKU Register'!H31="","",'Inputs - SKU Register'!H31) | L11: =IF(OR(E11="",I11=""),"",E11*I11) | M11: =IF(OR(L11="",K11=""),"",L11*K11) | N11: Enter sourced market rent, planned count, average SF, and stabilized occupancy.
C12: Two bedroom | D12: REV-TWOBR-01 | E12: =IF('Inputs - SKU Register'!H32="","",'Inputs - SKU Register'!H32) | F12: REV-TWOBR-02 | G12: =IF('Inputs - SKU Register'!H33="","",'Inputs - SKU Register'!H33) | H12: REV-TWOBR-03 | I12: =IF('Inputs - SKU Register'!H34="","",'Inputs - SKU Register'!H34) | J12: REV-TWOBR-04 | K12: =IF('Inputs - SKU Register'!H35="","",'Inputs - SKU Register'!H35) | L12: =IF(OR(E12="",I12=""),"",E12*I12) | M12: =IF(OR(L12="",K12=""),"",L12*K12) | N12: Enter sourced market rent, planned count, average SF, and stabilized occupancy.
C13: Three bedroom | D13: REV-THREEBR-01 | E13: =IF('Inputs - SKU Register'!H36="","",'Inputs - SKU Register'!H36) | F13: REV-THREEBR-02 | G13: =IF('Inputs - SKU Register'!H37="","",'Inputs - SKU Register'!H37) | H13: REV-THREEBR-03 | I13: =IF('Inputs - SKU Register'!H38="","",'Inputs - SKU Register'!H38) | J13: REV-THREEBR-04 | K13: =IF('Inputs - SKU Register'!H39="","",'Inputs - SKU Register'!H39) | L13: =IF(OR(E13="",I13=""),"",E13*I13) | M13: =IF(OR(L13="",K13=""),"",L13*K13) | N13: Enter sourced market rent, planned count, average SF, and stabilized occupancy.
C14: Total / weighted output | E14: =SUM(E10:E13) -> 0 | L14: =IF(COUNT(L10:L13)=0,"",SUM(L10:L13)) | M14: =IF(COUNT(M10:M13)=0,"",SUM(M10:M13))
C15: Unit-count check | E15: =E14-'Inputs - SKU Register'!$H$11 -> -280 | N15: Must equal zero before the working unit mix is treated as reconciling to the historical program reference.

Sheet Revenue & Operations
C3: Cedarwood Flats | Operating Statement
C5: Base-case operating build. All operating inputs are scenario drivers, and blank drivers remain blank rather than being treated as zero.
C6: ($ in whole dollars unless noted)
C8: STABILIZED ANNUAL OPERATING STATEMENT
C9: SKU / Line | D9: Description | E9: Annual Amount | F9: Driver Link / Formula | G9: State | H9: Notes
C10: REV-100 | D10: Gross potential rent | E10: =IF('Rent Roll'!L14="","",'Rent Roll'!L14*12) | F10: Rent Roll monthly GPR × 12 | G10: Formula | H10: Unavailable until unit mix and market rents are entered.
C11: REV-101 | D11: Other income | E11: =IF(OR('Rent Roll'!M14="",'Inputs - SKU Register'!H40=""),"",'Rent Roll'!M14*'Inputs - SKU Register'!H40*12) | F11: Occupied units × other income per occupied unit × 12 | G11: Formula
C12: REV-102 | D12: Concessions and bad debt | E12: =IF(OR(E10="",'Inputs - SKU Register'!H41=""),"",-E10*'Inputs - SKU Register'!H41) | G12: Formula
C13: REV-103 | D13: Effective gross income | E13: =IF(COUNT(E10:E12)=0,"",SUM(E10:E12)) | G13: Formula
C15: OPX-001 | D15: Real estate taxes | E15: =IF('Inputs - SKU Register'!H46="","",-'Inputs - SKU Register'!H46) | F15: Input SKU OPX-001 | G15: Projected input
C16: OPX-002 | D16: Property insurance | E16: =IF('Inputs - SKU Register'!H47="","",-'Inputs - SKU Register'!H47) | F16: Input SKU OPX-002 | G16: Projected input
C17: OPX-003 | D17: Property management | E17: =IF('Inputs - SKU Register'!H48="","",-'Inputs - SKU Register'!H48) | F17: Input SKU OPX-003 | G17: Projected input
C18: OPX-004 | D18: Payroll and benefits | E18: =IF('Inputs - SKU Register'!H49="","",-'Inputs - SKU Register'!H49) | F18: Input SKU OPX-004 | G18: Projected input
C19: OPX-005 | D19: Repairs and maintenance | E19: =IF('Inputs - SKU Register'!H50="","",-'Inputs - SKU Register'!H50) | F19: Input SKU OPX-005 | G19: Projected input
C20: OPX-006 | D20: Utilities | E20: =IF('Inputs - SKU Register'!H51="","",-'Inputs - SKU Register'!H51) | F20: Input SKU OPX-006 | G20: Projected input
C21: OPX-007 | D21: Contract services | E21: =IF('Inputs - SKU Register'!H52="","",-'Inputs - SKU Register'!H52) | F21: Input SKU OPX-007 | G21: Projected input
C22: OPX-008 | D22: Marketing and leasing | E22: =IF('Inputs - SKU Register'!H53="","",-'Inputs - SKU Register'!H53) | F22: Input SKU OPX-008 | G22: Projected input
C23: OPX-009 | D23: General and administrative | E23: =IF('Inputs - SKU Register'!H54="","",-'Inputs - SKU Register'!H54) | F23: Input SKU OPX-009 | G23: Projected input
C24: OPX-010 | D24: Turnover | E24: =IF('Inputs - SKU Register'!H55="","",-'Inputs - SKU Register'!H55) | F24: Input SKU OPX-010 | G24: Projected input
C25: OPX-011 | D25: Replacement reserves | E25: =IF('Inputs - SKU Register'!H56="","",-'Inputs - SKU Register'!H56) | F25: Input SKU OPX-011 | G25: Projected input
C26: OPX-012 | D26: HOA / common-area expense | E26: =IF('Inputs - SKU Register'!H57="","",-'Inputs - SKU Register'!H57) | F26: Input SKU OPX-012 | G26: Projected input
... C28: OPX-014 | D28: Other operating expense | E28: =IF('Inputs - SKU Register'!H59="","",-'Inputs - SKU Register'!H59) | F28: Input SKU OPX-014 | G28: Projected input
C29: NOI-001 | D29: Net operating income | E29: =IF(OR(E13="",COUNT(E15:E28)=0),"",E13+SUM(E15:E28)) | G29: Formula
C30: NOI-002 | D30: Variance to historical NOI reference | E30: =IF(E29="","",E29-'Inputs - SKU Register'!G18) | G30: Formula | H30: Reference comparison only. The historical NOI never forces the operating build.

Sheet Monthly Schedule
C3: Cedarwood Flats | 36-Month Construction, Lease-Up & Cash Flow
C5: Every month has explicit construction and occupancy SKU rows. Blank timing inputs remain blank and prevent modeled cash-flow output.
C6: ($ in whole dollars unless noted)
C8: BASE-CASE MONTHLY SCHEDULE
C9: Month | D9: Phase | E9: Construction SKU | F9: Construction % | G9: Construction Spend | H9: Occupancy SKU | I9: Occupancy | J9: Potential Rent | K9: EGI | L9: Operating Expenses | M9: NOI | N9: Debt Service | O9: Levered Cash Flow | P9: Notes
C10: 1 | D10: Enter lifecycle phase | E10: SCH-01-01 | F10: =IF('Inputs - SKU Register'!H63="","",'Inputs - SKU Register'!H63) | G10: =IF(F10="","",F10*'WBS Budget'!K110) | H10: SCH-01-02 | I10: =IF('Inputs - SKU Register'!H64="","",'Inputs - SKU Register'!H64) | J10: =IF(OR(I10="",'Revenue & Operations'!E10=""),"",'Revenue & Operations'!E10/12*I10) | K10: =IF(OR(J10="",'Inputs - SKU Register'!H40="",'Inputs - SKU Register'!H41="",'Rent Roll'!E14=""),"",J10*(1-'Inputs - SKU Register'!H41)+('Rent Roll'!E14*I10*'Inputs - SKU Register'!H40)) | L10: =IF(COUNT('Revenue & Operations'!E15:E28)=0,"",SUM('Revenue & Operations'!E15:E28)/12) | M10: =IF(OR(K10="",L10=""),"",K10+L10) | O10: =IF(OR(G10="",M10=""),"",M10-G10-N10) | P10: Debt service links once financing terms are entered.
C11: 2 | D11: Enter lifecycle phase | E11: SCH-02-01 | F11: =IF('Inputs - SKU Register'!H65="","",'Inputs - SKU Register'!H65) | G11: =IF(F11="","",F11*'WBS Budget'!K110) | H11: SCH-02-02 | I11: =IF('Inputs - SKU Register'!H66="","",'Inputs - SKU Register'!H66) | J11: =IF(OR(I11="",'Revenue & Operations'!E10=""),"",'Revenue & Operations'!E10/12*I11) | K11: =IF(OR(J11="",'Inputs - SKU Register'!H40="",'Inputs - SKU Register'!H41="",'Rent Roll'!E14=""),"",J11*(1-'Inputs - SKU Register'!H41)+('Rent Roll'!E14*I11*'Inputs - SKU Register'!H40)) | L11: =IF(COUNT('Revenue & Operations'!E15:E28)=0,"",SUM('Revenue & Operations'!E15:E28)/12) | M11: =IF(OR(K11="",L11=""),"",K11+L11) | O11: =IF(OR(G11="",M11=""),"",M11-G11-N11) | P11: Debt service links once financing terms are entered.
C12: 3 | D12: Enter lifecycle phase | E12: SCH-03-01 | F12: =IF('Inputs - SKU Register'!H67="","",'Inputs - SKU Register'!H67) | G12: =IF(F12="","",F12*'WBS Budget'!K110) | H12: SCH-03-02 | I12: =IF('Inputs - SKU Register'!H68="","",'Inputs - SKU Register'!H68) | J12: =IF(OR(I12="",'Revenue & Operations'!E10=""),"",'Revenue & Operations'!E10/12*I12) | K12: =IF(OR(J12="",'Inputs - SKU Register'!H40="",'Inputs - SKU Register'!H41="",'Rent Roll'!E14=""),"",J12*(1-'Inputs - SKU Register'!H41)+('Rent Roll'!E14*I12*'Inputs - SKU Register'!H40)) | L12: =IF(COUNT('Revenue & Operations'!E15:E28)=0,"",SUM('Revenue & Operations'!E15:E28)/12) | M12: =IF(OR(K12="",L12=""),"",K12+L12) | O12: =IF(OR(G12="",M12=""),"",M12-G12-N12) | P12: Debt service links once financing terms are entered.
C13: 4 | D13: Enter lifecycle phase | E13: SCH-04-01 | F13: =IF('Inputs - SKU Register'!H69="","",'Inputs - SKU Register'!H69) | G13: =IF(F13="","",F13*'WBS Budget'!K110) | H13: SCH-04-02 | I13: =IF('Inputs - SKU Register'!H70="","",'Inputs - SKU Register'!H70) | J13: =IF(OR(I13="",'Revenue & Operations'!E10=""),"",'Revenue & Operations'!E10/12*I13) | K13: =IF(OR(J13="",'Inputs - SKU Register'!H40="",'Inputs - SKU Register'!H41="",'Rent Roll'!E14=""),"",J13*(1-'Inputs - SKU Register'!H41)+('Rent Roll'!E14*I13*'Inputs - SKU Register'!H40)) | L13: =IF(COUNT('Revenue & Operations'!E15:E28)=0,"",SUM('Revenue & Operations'!E15:E28)/12) | M13: =IF(OR(K13="",L13=""),"",K13+L13) | O13: =IF(OR(G13="",M13=""),"",M13-G13-N13) | P13: Debt service links once financing terms are entered.
C14: 5 | D14: Enter lifecycle phase | E14: SCH-05-01 | F14: =IF('Inputs - SKU Register'!H71="","",'Inputs - SKU Register'!H71) | G14: =IF(F14="","",F14*'WBS Budget'!K110) | H14: SCH-05-02 | I14: =IF('Inputs - SKU Register'!H72="","",'Inputs - SKU Register'!H72) | J14: =IF(OR(I14="",'Revenue & Operations'!E10=""),"",'Revenue & Operations'!E10/12*I14) | K14: =IF(OR(J14="",'Inputs - SKU Register'!H40="",'Inputs - SKU Register'!H41="",'Rent Roll'!E14=""),"",J14*(1-'Inputs - SKU Register'!H41)+('Rent Roll'!E14*I14*'Inputs - SKU Register'!H40)) | L14: =IF(COUNT('Revenue & Operations'!E15:E28)=0,"",SUM('Revenue & Operations'!E15:E28)/12) | M14: =IF(OR(K14="",L14=""),"",K14+L14) | O14: =IF(OR(G14="",M14=""),"",M14-G14-N14) | P14: Debt service links once financing terms are entered.
C15: 6 | D15: Enter lifecycle phase | E15: SCH-06-01 | F15: =IF('Inputs - SKU Register'!H73="","",'Inputs - SKU Register'!H73) | G15: =IF(F15="","",F15*'WBS Budget'!K110) | H15: SCH-06-02 | I15: =IF('Inputs - SKU Register'!H74="","",'Inputs - SKU Register'!H74) | J15: =IF(OR(I15="",'Revenue & Operations'!E10=""),"",'Revenue & Operations'!E10/12*I15) | K15: =IF(OR(J15="",'Inputs - SKU Register'!H40="",'Inputs - SKU Register'!H41="",'Rent Roll'!E14=""),"",J15*(1-'Inputs - SKU Register'!H41)+('Rent Roll'!E14*I15*'Inputs - SKU Register'!H40)) | L15: =IF(COUNT('Revenue & Operations'!E15:E28)=0,"",SUM('Revenue & Operations'!E15:E28)/12) | M15: =IF(OR(K15="",L15=""),"",K15+L15) | O15: =IF(OR(G15="",M15=""),"",M15-G15-N15) | P15: Debt service links once financing terms are entered.
C16: 7 | D16: Enter lifecycle phase | E16: SCH-07-01 | F16: =IF('Inputs - SKU Register'!H75="","",'Inputs - SKU Register'!H75) | G16: =IF(F16="","",F16*'WBS Budget'!K110) | H16: SCH-07-02 | I16: =IF('Inputs - SKU Register'!H76="","",'Inputs - SKU Register'!H76) | J16: =IF(OR(I16="",'Revenue & Operations'!E10=""),"",'Revenue & Operations'!E10/12*I16) | K16: =IF(OR(J16="",'Inputs - SKU Register'!H40="",'Inputs - SKU Register'!H41="",'Rent Roll'!E14=""),"",J16*(1-'Inputs - SKU Register'!H41)+('Rent Roll'!E14*I16*'Inputs - SKU Register'!H40)) | L16: =IF(COUNT('Revenue & Operations'!E15:E28)=0,"",SUM('Revenue & Operations'!E15:E28)/12) | M16: =IF(OR(K16="",L16=""),"",K16+L16) | O16: =IF(OR(G16="",M16=""),"",M16-G16-N16) | P16: Debt service links once financing terms are entered.
C17: 8 | D17: Enter lifecycle phase | E17: SCH-08-01 | F17: =IF('Inputs - SKU Register'!H77="","",'Inputs - SKU Register'!H77) | G17: =IF(F17="","",F17*'WBS Budget'!K110) | H17: SCH-08-02 | I17: =IF('Inputs - SKU Register'!H78="","",'Inputs - SKU Register'!H78) | J17: =IF(OR(I17="",'Revenue & Operations'!E10=""),"",'Revenue & Operations'!E10/12*I17) | K17: =IF(OR(J17="",'Inputs - SKU Register'!H40="",'Inputs - SKU Register'!H41="",'Rent Roll'!E14=""),"",J17*(1-'Inputs - SKU Register'!H41)+('Rent Roll'!E14*I17*'Inputs - SKU Register'!H40)) | L17: =IF(COUNT('Revenue & Operations'!E15:E28)=0,"",SUM('Revenue & Operations'!E15:E28)/12) | M17: =IF(OR(K17="",L17=""),"",K17+L17) | O17: =IF(OR(G17="",M17=""),"",M17-G17-N17) | P17: Debt service links once financing terms are entered.
C18: 9 | D18: Enter lifecycle phase | E18: SCH-09-01 | F18: =IF('Inputs - SKU Register'!H79="","",'Inputs - SKU Register'!H79) | G18: =IF(F18="","",F18*'WBS Budget'!K110) | H18: SCH-09-02 | I18: =IF('Inputs - SKU Register'!H80="","",'Inputs - SKU Register'!H80) | J18: =IF(OR(I18="",'Revenue & Operations'!E10=""),"",'Revenue & Operations'!E10/12*I18) | K18: =IF(OR(J18="",'Inputs - SKU Register'!H40="",'Inputs - SKU Register'!H41="",'Rent Roll'!E14=""),"",J18*(1-'Inputs - SKU Register'!H41)+('Rent Roll'!E14*I18*'Inputs - SKU Register'!H40)) | L18: =IF(COUNT('Revenue & Operations'!E15:E28)=0,"",SUM('Revenue & Operations'!E15:E28)/12) | M18: =IF(OR(K18="",L18=""),"",K18+L18) | O18: =IF(OR(G18="",M18=""),"",M18-G18-N18) | P18: Debt service links once financing terms are entered.
C19: 10 | D19: Enter lifecycle phase | E19: SCH-10-01 | F19: =IF('Inputs - SKU Register'!H81="","",'Inputs - SKU Register'!H81) | G19: =IF(F19="","",F19*'WBS Budget'!K110) | H19: SCH-10-02 | I19: =IF('Inputs - SKU Register'!H82="","",'Inputs - SKU Register'!H82) | J19: =IF(OR(I19="",'Revenue & Operations'!E10=""),"",'Revenue & Operations'!E10/12*I19) | K19: =IF(OR(J19="",'Inputs - SKU Register'!H40="",'Inputs - SKU Register'!H41="",'Rent Roll'!E14=""),"",J19*(1-'Inputs - SKU Register'!H41)+('Rent Roll'!E14*I19*'Inputs - SKU Register'!H40)) | L19: =IF(COUNT('Revenue & Operations'!E15:E28)=0,"",SUM('Revenue & Operations'!E15:E28)/12) | M19: =IF(OR(K19="",L19=""),"",K19+L19) | O19: =IF(OR(G19="",M19=""),"",M19-G19-N19) | P19: Debt service links once financing terms are entered.
C20: 11 | D20: Enter lifecycle phase | E20: SCH-11-01 | F20: =IF('Inputs - SKU Register'!H83="","",'Inputs - SKU Register'!H83) | G20: =IF(F20="","",F20*'WBS Budget'!K110) | H20: SCH-11-02 | I20: =IF('Inputs - SKU Register'!H84="","",'Inputs - SKU Register'!H84) | J20: =IF(OR(I20="",'Revenue & Operations'!E10=""),"",'Revenue & Operations'!E10/12*I20) | K20: =IF(OR(J20="",'Inputs - SKU Register'!H40="",'Inputs - SKU Register'!H41="",'Rent Roll'!E14=""),"",J20*(1-'Inputs - SKU Register'!H41)+('Rent Roll'!E14*I20*'Inputs - SKU Register'!H40)) | L20: =IF(COUNT('Revenue & Operations'!E15:E28)=0,"",SUM('Revenue & Operations'!E15:E28)/12) | M20: =IF(OR(K20="",L20=""),"",K20+L20) | O20: =IF(OR(G20="",M20=""),"",M20-G20-N20) | P20: Debt service links once financing terms are entered.
C21: 12 | D21: Enter lifecycle phase | E21: SCH-12-01 | F21: =IF('Inputs - SKU Register'!H85="","",'Inputs - SKU Register'!H85) | G21: =IF(F21="","",F21*'WBS Budget'!K110) | H21: SCH-12-02 | I21: =IF('Inputs - SKU Register'!H86="","",'Inputs - SKU Register'!H86) | J21: =IF(OR(I21="",'Revenue & Operations'!E10=""),"",'Revenue & Operations'!E10/12*I21) | K21: =IF(OR(J21="",'Inputs - SKU Register'!H40="",'Inputs - SKU Register'!H41="",'Rent Roll'!E14=""),"",J21*(1-'Inputs - SKU Register'!H41)+('Rent Roll'!E14*I21*'Inputs - SKU Register'!H40)) | L21: =IF(COUNT('Revenue & Operations'!E15:E28)=0,"",SUM('Revenue & Operations'!E15:E28)/12) | M21: =IF(OR(K21="",L21=""),"",K21+L21) | O21: =IF(OR(G21="",M21=""),"",M21-G21-N21) | P21: Debt service links once financing terms are entered.
C22: 13 | D22: Enter lifecycle phase | E22: SCH-13-01 | F22: =IF('Inputs - SKU Register'!H87="","",'Inputs - SKU Register'!H87) | G22: =IF(F22="","",F22*'WBS Budget'!K110) | H22: SCH-13-02 | I22: =IF('Inputs - SKU Register'!H88="","",'Inputs - SKU Register'!H88) | J22: =IF(OR(I22="",'Revenue & Operations'!E10=""),"",'Revenue & Operations'!E10/12*I22) | K22: =IF(OR(J22="",'Inputs - SKU Register'!H40="",'Inputs - SKU Register'!H41="",'Rent Roll'!E14=""),"",J22*(1-'Inputs - SKU Register'!H41)+('Rent Roll'!E14*I22*'Inputs - SKU Register'!H40)) | L22: =IF(COUNT('Revenue & Operations'!E15:E28)=0,"",SUM('Revenue & Operations'!E15:E28)/12) | M22: =IF(OR(K22="",L22=""),"",K22+L22) | O22: =IF(OR(G22="",M22=""),"",M22-G22-N22) | P22: Debt service links once financing terms are entered.
C23: 14 | D23: Enter lifecycle phase | E23: SCH-14-01 | F23: =IF('Inputs - SKU Register'!H89="","",'Inputs - SKU Register'!H89) | G23: =IF(F23="","",F23*'WBS Budget'!K110) | H23: SCH-14-02 | I23: =IF('Inputs - SKU Register'!H90="","",'Inputs - SKU Register'!H90) | J23: =IF(OR(I23="",'Revenue & Operations'!E10=""),"",'Revenue & Operations'!E10/12*I23) | K23: =IF(OR(J23="",'Inputs - SKU Register'!H40="",'Inputs - SKU Register'!H41="",'Rent Roll'!E14=""),"",J23*(1-'Inputs - SKU Register'!H41)+('Rent Roll'!E14*I23*'Inputs - SKU Register'!H40)) | L23: =IF(COUNT('Revenue & Operations'!E15:E28)=0,"",SUM('Revenue & Operations'!E15:E28)/12) | M23: =IF(OR(K23="",L23=""),"",K23+L23) | O23: =IF(OR(G23="",M23=""),"",M23-G23-N23) | P23: Debt service links once financing terms are entered.
C24: 15 | D24: Enter lifecycle phase | E24: SCH-15-01 | F24: =IF('Inputs - SKU Register'!H91="","",'Inputs - SKU Register'!H91) | G24: =IF(F24="","",F24*'WBS Budget'!K110) | H24: SCH-15-02 | I24: =IF('Inputs - SKU Register'!H92="","",'Inputs - SKU Register'!H92) | J24: =IF(OR(I24="",'Revenue & Operations'!E10=""),"",'Revenue & Operations'!E10/12*I24) | K24: =IF(OR(J24="",'Inputs - SKU Register'!H40="",'Inputs - SKU Register'!H41="",'Rent Roll'!E14=""),"",J24*(1-'Inputs - SKU Register'!H41)+('Rent Roll'!E14*I24*'Inputs - SKU Register'!H40)) | L24: =IF(COUNT('Revenue & Operations'!E15:E28)=0,"",SUM('Revenue & Operations'!E15:E28)/12) | M24: =IF(OR(K24="",L24=""),"",K24+L24) | O24: =IF(OR(G24="",M24=""),"",M24-G24-N24) | P24: Debt service links once financing terms are entered.
C25: 16 | D25: Enter lifecycle phase | E25: SCH-16-01 | F25: =IF('Inputs - SKU Register'!H93="","",'Inputs - SKU Register'!H93) | G25: =IF(F25="","",F25*'WBS Budget'!K110) | H25: SCH-16-02 | I25: =IF('Inputs - SKU Register'!H94="","",'Inputs - SKU Register'!H94) | J25: =IF(OR(I25="",'Revenue & Operations'!E10=""),"",'Revenue & Operations'!E10/12*I25) | K25: =IF(OR(J25="",'Inputs - SKU Register'!H40="",'Inputs - SKU Register'!H41="",'Rent Roll'!E14=""),"",J25*(1-'Inputs - SKU Register'!H41)+('Rent Roll'!E14*I25*'Inputs - SKU Register'!H40)) | L25: =IF(COUNT('Revenue & Operations'!E15:E28)=0,"",SUM('Revenue & Operations'!E15:E28)/12) | M25: =IF(OR(K25="",L25=""),"",K25+L25) | O25: =IF(OR(G25="",M25=""),"",M25-G25-N25) | P25: Debt service links once financing terms are entered.
C26: 17 | D26: Enter lifecycle phase | E26: SCH-17-01 | F26: =IF('Inputs - SKU Register'!H95="","",'Inputs - SKU Register'!H95) | G26: =IF(F26="","",F26*'WBS Budget'!K110) | H26: SCH-17-02 | I26: =IF('Inputs - SKU Register'!H96="","",'Inputs - SKU Register'!H96) | J26: =IF(OR(I26="",'Revenue & Operations'!E10=""),"",'Revenue & Operations'!E10/12*I26) | K26: =IF(OR(J26="",'Inputs - SKU Register'!H40="",'Inputs - SKU Register'!H41="",'Rent Roll'!E14=""),"",J26*(1-'Inputs - SKU Register'!H41)+('Rent Roll'!E14*I26*'Inputs - SKU Register'!H40)) | L26: =IF(COUNT('Revenue & Operations'!E15:E28)=0,"",SUM('Revenue & Operations'!E15:E28)/12) | M26: =IF(OR(K26="",L26=""),"",K26+L26) | O26: =IF(OR(G26="",M26=""),"",M26-G26-N26) | P26: Debt service links once financing terms are entered.
C27: 18 | D27: Enter lifecycle phase | E27: SCH-18-01 | F27: =IF('Inputs - SKU Register'!H97="","",'Inputs - SKU Register'!H97) | G27: =IF(F27="","",F27*'WBS Budget'!K110) | H27: SCH-18-02 | I27: =IF('Inputs - SKU Register'!H98="","",'Inputs - SKU Register'!H98) | J27: =IF(OR(I27="",'Revenue & Operations'!E10=""),"",'Revenue & Operations'!E10/12*I27) | K27: =IF(OR(J27="",'Inputs - SKU Register'!H40="",'Inputs - SKU Register'!H41="",'Rent Roll'!E14=""),"",J27*(1-'Inputs - SKU Register'!H41)+('Rent Roll'!E14*I27*'Inputs - SKU Register'!H40)) | L27: =IF(COUNT('Revenue & Operations'!E15:E28)=0,"",SUM('Revenue & Operations'!E15:E28)/12) | M27: =IF(OR(K27="",L27=""),"",K27+L27) | O27: =IF(OR(G27="",M27=""),"",M27-G27-N27) | P27: Debt service links once financing terms are entered.
C28: 19 | D28: Enter lifecycle phase | E28: SCH-19-01 | F28: =IF('Inputs - SKU Register'!H99="","",'Inputs - SKU Register'!H99) | G28: =IF(F28="","",F28*'WBS Budget'!K110) | H28: SCH-19-02 | I28: =IF('Inputs - SKU Register'!H100="","",'Inputs - SKU Register'!H100) | J28: =IF(OR(I28="",'Revenue & Operations'!E10=""),"",'Revenue & Operations'!E10/12*I28) | K28: =IF(OR(J28="",'Inputs - SKU Register'!H40="",'Inputs - SKU Register'!H41="",'Rent Roll'!E14=""),"",J28*(1-'Inputs - SKU Register'!H41)+('Rent Roll'!E14*I28*'Inputs - SKU Register'!H40)) | L28: =IF(COUNT('Revenue & Operations'!E15:E28)=0,"",SUM('Revenue & Operations'!E15:E28)/12) | M28: =IF(OR(K28="",L28=""),"",K28+L28) | O28: =IF(OR(G28="",M28=""),"",M28-G28-N28) | P28: Debt service links once financing terms are entered.
C29: 20 | D29: Enter lifecycle phase | E29: SCH-20-01 | F29: =IF('Inputs - SKU Register'!H101="","",'Inputs - SKU Register'!H101) | G29: =IF(F29="","",F29*'WBS Budget'!K110) | H29: SCH-20-02 | I29: =IF('Inputs - SKU Register'!H102="","",'Inputs - SKU Register'!H102) | J29: =IF(OR(I29="",'Revenue & Operations'!E10=""),"",'Revenue & Operations'!E10/12*I29) | K29: =IF(OR(J29="",'Inputs - SKU Register'!H40="",'Inputs - SKU Register'!H41="",'Rent Roll'!E14=""),"",J29*(1-'Inputs - SKU Register'!H41)+('Rent Roll'!E14*I29*'Inputs - SKU Register'!H40)) | L29: =IF(COUNT('Revenue & Operations'!E15:E28)=0,"",SUM('Revenue & Operations'!E15:E28)/12) | M29: =IF(OR(K29="",L29=""),"",K29+L29) | O29: =IF(OR(G29="",M29=""),"",M29-G29-N29) | P29: Debt service links once financing terms are entered.
C30: 21 | D30: Enter lifecycle phase | E30: SCH-21-01 | F30: =IF('Inputs - SKU Register'!H103="","",'Inputs - SKU Register'!H103) | G30: =IF(F30="","",F30*'WBS Budget'!K110) | H30: SCH-21-02 | I30: =IF('Inputs - SKU Register'!H104="","",'Inputs - SKU Register'!H104) | J30: =IF(OR(I30="",'Revenue & Operations'!E10=""),"",'Revenue & Operations'!E10/12*I30) | K30: =IF(OR(J30="",'Inputs - SKU Register'!H40="",'Inputs - SKU Register'!H41="",'Rent Roll'!E14=""),"",J30*(1-'Inputs - SKU Register'!H41)+('Rent Roll'!E14*I30*'Inputs - SKU Register'!H40)) | L30: =IF(COUNT('Revenue & Operations'!E15:E28)=0,"",SUM('Revenue & Operations'!E15:E28)/12) | M30: =IF(OR(K30="",L30=""),"",K30+L30) | O30: =IF(OR(G30="",M30=""),"",M30-G30-N30) | P30: Debt service links once financing terms are entered.
C31: 22 | D31: Enter lifecycle phase | E31: SCH-22-01 | F31: =IF('Inputs - SKU Register'!H105="","",'Inputs - SKU Register'!H105) | G31: =IF(F31="","",F31*'WBS Budget'!K110) | H31: SCH-22-02 | I31: =IF('Inputs - SKU Register'!H106="","",'Inputs - SKU Register'!H106) | J31: =IF(OR(I31="",'Revenue & Operations'!E10=""),"",'Revenue & Operations'!E10/12*I31) | K31: =IF(OR(J31="",'Inputs - SKU Register'!H40="",'Inputs - SKU Register'!H41="",'Rent Roll'!E14=""),"",J31*(1-'Inputs - SKU Register'!H41)+('Rent Roll'!E14*I31*'Inputs - SKU Register'!H40)) | L31: =IF(COUNT('Revenue & Operations'!E15:E28)=0,"",SUM('Revenue & Operations'!E15:E28)/12) | M31: =IF(OR(K31="",L31=""),"",K31+L31) | O31: =IF(OR(G31="",M31=""),"",M31-G31-N31) | P31: Debt service links once financing terms are entered.
C32: 23 | D32: Enter lifecycle phase | E32: SCH-23-01 | F32: =IF('Inputs - SKU Register'!H107="","",'Inputs - SKU Register'!H107) | G32: =IF(F32="","",F32*'WBS Budget'!K110) | H32: SCH-23-02 | I32: =IF('Inputs - SKU Register'!H108="","",'Inputs - SKU Register'!H108) | J32: =IF(OR(I32="",'Revenue & Operations'!E10=""),"",'Revenue & Operations'!E10/12*I32) | K32: =IF(OR(J32="",'Inputs - SKU Register'!H40="",'Inputs - SKU Register'!H41="",'Rent Roll'!E14=""),"",J32*(1-'Inputs - SKU Register'!H41)+('Rent Roll'!E14*I32*'Inputs - SKU Register'!H40)) | L32: =IF(COUNT('Revenue & Operations'!E15:E28)=0,"",SUM('Revenue & Operations'!E15:E28)/12) | M32: =IF(OR(K32="",L32=""),"",K32+L32) | O32: =IF(OR(G32="",M32=""),"",M32-G32-N32) | P32: Debt service links once financing terms are entered.
C33: 24 | D33: Enter lifecycle phase | E33: SCH-24-01 | F33: =IF('Inputs - SKU Register'!H109="","",'Inputs - SKU Register'!H109) | G33: =IF(F33="","",F33*'WBS Budget'!K110) | H33: SCH-24-02 | I33: =IF('Inputs - SKU Register'!H110="","",'Inputs - SKU Register'!H110) | J33: =IF(OR(I33="",'Revenue & Operations'!E10=""),"",'Revenue & Operations'!E10/12*I33) | K33: =IF(OR(J33="",'Inputs - SKU Register'!H40="",'Inputs - SKU Register'!H41="",'Rent Roll'!E14=""),"",J33*(1-'Inputs - SKU Register'!H41)+('Rent Roll'!E14*I33*'Inputs - SKU Register'!H40)) | L33: =IF(COUNT('Revenue & Operations'!E15:E28)=0,"",SUM('Revenue & Operations'!E15:E28)/12) | M33: =IF(OR(K33="",L33=""),"",K33+L33) | O33: =IF(OR(G33="",M33=""),"",M33-G33-N33) | P33: Debt service links once financing terms are entered.
C34: 25 | D34: Enter lifecycle phase | E34: SCH-25-01 | F34: =IF('Inputs - SKU Register'!H111="","",'Inputs - SKU Register'!H111) | G34: =IF(F34="","",F34*'WBS Budget'!K110) | H34: SCH-25-02 | I34: =IF('Inputs - SKU Register'!H112="","",'Inputs - SKU Register'!H112) | J34: =IF(OR(I34="",'Revenue & Operations'!E10=""),"",'Revenue & Operations'!E10/12*I34) | K34: =IF(OR(J34="",'Inputs - SKU Register'!H40="",'Inputs - SKU Register'!H41="",'Rent Roll'!E14=""),"",J34*(1-'Inputs - SKU Register'!H41)+('Rent Roll'!E14*I34*'Inputs - SKU Register'!H40)) | L34: =IF(COUNT('Revenue & Operations'!E15:E28)=0,"",SUM('Revenue & Operations'!E15:E28)/12) | M34: =IF(OR(K34="",L34=""),"",K34+L34) | O34: =IF(OR(G34="",M34=""),"",M34-G34-N34) | P34: Debt service links once financing terms are entered.
C35: 26 | D35: Enter lifecycle phase | E35: SCH-26-01 | F35: =IF('Inputs - SKU Register'!H113="","",'Inputs - SKU Register'!H113) | G35: =IF(F35="","",F35*'WBS Budget'!K110) | H35: SCH-26-02 | I35: =IF('Inputs - SKU Register'!H114="","",'Inputs - SKU Register'!H114) | J35: =IF(OR(I35="",'Revenue & Operations'!E10=""),"",'Revenue & Operations'!E10/12*I35) | K35: =IF(OR(J35="",'Inputs - SKU Register'!H40="",'Inputs - SKU Register'!H41="",'Rent Roll'!E14=""),"",J35*(1-'Inputs - SKU Register'!H41)+('Rent Roll'!E14*I35*'Inputs - SKU Register'!H40)) | L35: =IF(COUNT('Revenue & Operations'!E15:E28)=0,"",SUM('Revenue & Operations'!E15:E28)/12) | M35: =IF(OR(K35="",L35=""),"",K35+L35) | O35: =IF(OR(G35="",M35=""),"",M35-G35-N35) | P35: Debt service links once financing terms are entered.
C36: 27 | D36: Enter lifecycle phase | E36: SCH-27-01 | F36: =IF('Inputs - SKU Register'!H115="","",'Inputs - SKU Register'!H115) | G36: =IF(F36="","",F36*'WBS Budget'!K110) | H36: SCH-27-02 | I36: =IF('Inputs - SKU Register'!H116="","",'Inputs - SKU Register'!H116) | J36: =IF(OR(I36="",'Revenue & Operations'!E10=""),"",'Revenue & Operations'!E10/12*I36) | K36: =IF(OR(J36="",'Inputs - SKU Register'!H40="",'Inputs - SKU Register'!H41="",'Rent Roll'!E14=""),"",J36*(1-'Inputs - SKU Register'!H41)+('Rent Roll'!E14*I36*'Inputs - SKU Register'!H40)) | L36: =IF(COUNT('Revenue & Operations'!E15:E28)=0,"",SUM('Revenue & Operations'!E15:E28)/12) | M36: =IF(OR(K36="",L36=""),"",K36+L36) | O36: =IF(OR(G36="",M36=""),"",M36-G36-N36) | P36: Debt service links once financing terms are entered.
C37: 28 | D37: Enter lifecycle phase | E37: SCH-28-01 | F37: =IF('Inputs - SKU Register'!H117="","",'Inputs - SKU Register'!H117) | G37: =IF(F37="","",F37*'WBS Budget'!K110) | H37: SCH-28-02 | I37: =IF('Inputs - SKU Register'!H118="","",'Inputs - SKU Register'!H118) | J37: =IF(OR(I37="",'Revenue & Operations'!E10=""),"",'Revenue & Operations'!E10/12*I37) | K37: =IF(OR(J37="",'Inputs - SKU Register'!H40="",'Inputs - SKU Register'!H41="",'Rent Roll'!E14=""),"",J37*(1-'Inputs - SKU Register'!H41)+('Rent Roll'!E14*I37*'Inputs - SKU Register'!H40)) | L37: =IF(COUNT('Revenue & Operations'!E15:E28)=0,"",SUM('Revenue & Operations'!E15:E28)/12) | M37: =IF(OR(K37="",L37=""),"",K37+L37) | O37: =IF(OR(G37="",M37=""),"",M37-G37-N37) | P37: Debt service links once financing terms are entered.
C38: 29 | D38: Enter lifecycle phase | E38: SCH-29-01 | F38: =IF('Inputs - SKU Register'!H119="","",'Inputs - SKU Register'!H119) | G38: =IF(F38="","",F38*'WBS Budget'!K110) | H38: SCH-29-02 | I38: =IF('Inputs - SKU Register'!H120="","",'Inputs - SKU Register'!H120) | J38: =IF(OR(I38="",'Revenue & Operations'!E10=""),"",'Revenue & Operations'!E10/12*I38) | K38: =IF(OR(J38="",'Inputs - SKU Register'!H40="",'Inputs - SKU Register'!H41="",'Rent Roll'!E14=""),"",J38*(1-'Inputs - SKU Register'!H41)+('Rent Roll'!E14*I38*'Inputs - SKU Register'!H40)) | L38: =IF(COUNT('Revenue & Operations'!E15:E28)=0,"",SUM('Revenue & Operations'!E15:E28)/12) | M38: =IF(OR(K38="",L38=""),"",K38+L38) | O38: =IF(OR(G38="",M38=""),"",M38-G38-N38) | P38: Debt service links once financing terms are entered.
C39: 30 | D39: Enter lifecycle phase | E39: SCH-30-01 | F39: =IF('Inputs - SKU Register'!H121="","",'Inputs - SKU Register'!H121) | G39: =IF(F39="","",F39*'WBS Budget'!K110) | H39: SCH-30-02 | I39: =IF('Inputs - SKU Register'!H122="","",'Inputs - SKU Register'!H122) | J39: =IF(OR(I39="",'Revenue & Operations'!E10=""),"",'Revenue & Operations'!E10/12*I39) | K39: =IF(OR(J39="",'Inputs - SKU Register'!H40="",'Inputs - SKU Register'!H41="",'Rent Roll'!E14=""),"",J39*(1-'Inputs - SKU Register'!H41)+('Rent Roll'!E14*I39*'Inputs - SKU Register'!H40)) | L39: =IF(COUNT('Revenue & Operations'!E15:E28)=0,"",SUM('Revenue & Operations'!E15:E28)/12) | M39: =IF(OR(K39="",L39=""),"",K39+L39) | O39: =IF(OR(G39="",M39=""),"",M39-G39-N39) | P39: Debt service links once financing terms are entered.
C40: 31 | D40: Enter lifecycle phase | E40: SCH-31-01 | F40: =IF('Inputs - SKU Register'!H123="","",'Inputs - SKU Register'!H123) | G40: =IF(F40="","",F40*'WBS Budget'!K110) | H40: SCH-31-02 | I40: =IF('Inputs - SKU Register'!H124="","",'Inputs - SKU Register'!H124) | J40: =IF(OR(I40="",'Revenue & Operations'!E10=""),"",'Revenue & Operations'!E10/12*I40) | K40: =IF(OR(J40="",'Inputs - SKU Register'!H40="",'Inputs - SKU Register'!H41="",'Rent Roll'!E14=""),"",J40*(1-'Inputs - SKU Register'!H41)+('Rent Roll'!E14*I40*'Inputs - SKU Register'!H40)) | L40: =IF(COUNT('Revenue & Operations'!E15:E28)=0,"",SUM('Revenue & Operations'!E15:E28)/12) | M40: =IF(OR(K40="",L40=""),"",K40+L40) | O40: =IF(OR(G40="",M40=""),"",M40-G40-N40) | P40: Debt service links once financing terms are entered.
C41: 32 | D41: Enter lifecycle phase | E41: SCH-32-01 | F41: =IF('Inputs - SKU Register'!H125="","",'Inputs - SKU Register'!H125) | G41: =IF(F41="","",F41*'WBS Budget'!K110) | H41: SCH-32-02 | I41: =IF('Inputs - SKU Register'!H126="","",'Inputs - SKU Register'!H126) | J41: =IF(OR(I41="",'Revenue & Operations'!E10=""),"",'Revenue & Operations'!E10/12*I41) | K41: =IF(OR(J41="",'Inputs - SKU Register'!H40="",'Inputs - SKU Register'!H41="",'Rent Roll'!E14=""),"",J41*(1-'Inputs - SKU Register'!H41)+('Rent Roll'!E14*I41*'Inputs - SKU Register'!H40)) | L41: =IF(COUNT('Revenue & Operations'!E15:E28)=0,"",SUM('Revenue & Operations'!E15:E28)/12) | M41: =IF(OR(K41="",L41=""),"",K41+L41) | O41: =IF(OR(G41="",M41=""),"",M41-G41-N41) | P41: Debt service links once financing terms are entered.
C42: 33 | D42: Enter lifecycle phase | E42: SCH-33-01 | F42: =IF('Inputs - SKU Register'!H127="","",'Inputs - SKU Register'!H127) | G42: =IF(F42="","",F42*'WBS Budget'!K110) | H42: SCH-33-02 | I42: =IF('Inputs - SKU Register'!H128="","",'Inputs - SKU Register'!H128) | J42: =IF(OR(I42="",'Revenue & Operations'!E10=""),"",'Revenue & Operations'!E10/12*I42) | K42: =IF(OR(J42="",'Inputs - SKU Register'!H40="",'Inputs - SKU Register'!H41="",'Rent Roll'!E14=""),"",J42*(1-'Inputs - SKU Register'!H41)+('Rent Roll'!E14*I42*'Inputs - SKU Register'!H40)) | L42: =IF(COUNT('Revenue & Operations'!E15:E28)=0,"",SUM('Revenue & Operations'!E15:E28)/12) | M42: =IF(OR(K42="",L42=""),"",K42+L42) | O42: =IF(OR(G42="",M42=""),"",M42-G42-N42) | P42: Debt service links once financing terms are entered.
C43: 34 | D43: Enter lifecycle phase | E43: SCH-34-01 | F43: =IF('Inputs - SKU Register'!H129="","",'Inputs - SKU Register'!H129) | G43: =IF(F43="","",F43*'WBS Budget'!K110) | H43: SCH-34-02 | I43: =IF('Inputs - SKU Register'!H130="","",'Inputs - SKU Register'!H130) | J43: =IF(OR(I43="",'Revenue & Operations'!E10=""),"",'Revenue & Operations'!E10/12*I43) | K43: =IF(OR(J43="",'Inputs - SKU Register'!H40="",'Inputs - SKU Register'!H41="",'Rent Roll'!E14=""),"",J43*(1-'Inputs - SKU Register'!H41)+('Rent Roll'!E14*I43*'Inputs - SKU Register'!H40)) | L43: =IF(COUNT('Revenue & Operations'!E15:E28)=0,"",SUM('Revenue & Operations'!E15:E28)/12) | M43: =IF(OR(K43="",L43=""),"",K43+L43) | O43: =IF(OR(G43="",M43=""),"",M43-G43-N43) | P43: Debt service links once financing terms are entered.
C44: 35 | D44: Enter lifecycle phase | E44: SCH-35-01 | F44: =IF('Inputs - SKU Register'!H131="","",'Inputs - SKU Register'!H131) | G44: =IF(F44="","",F44*'WBS Budget'!K110) | H44: SCH-35-02 | I44: =IF('Inputs - SKU Register'!H132="","",'Inputs - SKU Register'!H132) | J44: =IF(OR(I44="",'Revenue & Operations'!E10=""),"",'Revenue & Operations'!E10/12*I44) | K44: =IF(OR(J44="",'Inputs - SKU Register'!H40="",'Inputs - SKU Register'!H41="",'Rent Roll'!E14=""),"",J44*(1-'Inputs - SKU Register'!H41)+('Rent Roll'!E14*I44*'Inputs - SKU Register'!H40)) | L44: =IF(COUNT('Revenue & Operations'!E15:E28)=0,"",SUM('Revenue & Operations'!E15:E28)/12) | M44: =IF(OR(K44="",L44=""),"",K44+L44) | O44: =IF(OR(G44="",M44=""),"",M44-G44-N44) | P44: Debt service links once financing terms are entered.
...

Sheet Sources & Uses
C3: Cedarwood Flats | Sources & Uses
C5: The $55M financing figure is retained as a historical planning reference. Active sources use only editable base-case debt and equity SKUs.
C6: ($ in whole dollars unless noted)
C8: USES
C9: SKU | D9: Use | E9: Amount | F9: Source / Formula | G9: State | H9: Notes
C10: USE-001 | D10: Total development budget | E10: ='WBS Budget'!K110 -> 40000000 | F10: WBS Budget total | G10: Historical planning control
C12: SOURCES
C13: SKU | D13: Source | E13: Amount | F13: Source / Formula | G13: State | H13: Notes
C14: FIN-010 | D14: Senior debt | E14: =IF('Inputs - SKU Register'!H138="","",'Inputs - SKU Register'!H138) -> 55000000 | F14: Base-case input SKU FIN-010 | G14: Projected input
C15: CAP-001 | D15: Sponsor / JV equity | E15: =IF('Inputs - SKU Register'!H146="","",'Inputs - SKU Register'!H146) | F15: Base-case input SKU CAP-001 | G15: Projected input
C16: CAP-002 | D16: Other capital sources | E16: =IF('Inputs - SKU Register'!H147="","",'Inputs - SKU Register'!H147) | F16: Base-case input SKU CAP-002 | G16: Projected input
D17: Total sources | E17: =IF(COUNT(E14:E16)=0,"",SUM(E14:E16)) -> 55000000
D18: Sources / uses gap | E18: =IF(E17="","",E17-E10) -> 15000000 | G18: Formula
C20: FIN-001 | D20: Historical financing reference — not applied | E20: ='Inputs - SKU Register'!G20 -> 55000000 | G20: Historical planning reference | H20: Not funded capital. Copy or modify this reference into FIN-010 only when selecting an active debt case.

Sheet Debt Schedule
C3: Cedarwood Flats | Debt Schedule
C5: Debt service activates only after base-case financing SKU inputs are entered. Historical financing reference remains separate.
C6: ($ in whole dollars unless noted)
C8: BASE-CASE DEBT TERMS
C9: SKU | D9: Term | E9: Value | F9: Source | G9: State | H9: Notes
C10: FIN-010 | D10: Loan amount | E10: =IF('Inputs - SKU Register'!H138="","",'Inputs - SKU Register'!H138) -> 55000000 | F10: Base-case SKU FIN-010 | G10: Projected input
C11: FIN-011 | D11: Annual interest rate | E11: =IF('Inputs - SKU Register'!H139="","",'Inputs - SKU Register'!H139) | F11: Base-case SKU FIN-011 | G11: Projected input
C12: FIN-012 | D12: Financing fee | E12: =IF('Inputs - SKU Register'!H140="","",'Inputs - SKU Register'!H140) | F12: Base-case SKU FIN-012 | G12: Projected input
C13: FIN-013 | D13: Term | E13: =IF('Inputs - SKU Register'!H141="","",'Inputs - SKU Register'!H141) | F13: Base-case SKU FIN-013 | G13: Projected input
C14: FIN-014 | D14: Amortization | E14: =IF('Inputs - SKU Register'!H142="","",'Inputs - SKU Register'!H142) | F14: Base-case SKU FIN-014 | G14: Projected input
C15: FIN-015 | D15: Interest-only period | E15: =IF('Inputs - SKU Register'!H143="","",'Inputs - SKU Register'!H143) | F15: Base-case SKU FIN-015 | G15: Projected input
